Workbook

Sheet Dashboard
A1: Analytics Engineer Roadmap — Dashboard
A2: Everything here is calculated from the other sheets. Only the yellow cells are inputs.
A4: Settings
A5: Start date (Monday of week 1) | B5: 46293
A6: Weekly hours target (reference) | B6: 20
A7: Monthly income goal ($) | B7: 5000
A8: Today | B8: =TODAY() -> 46288
A10: Learning progress | D10: Upwork (analytics niche)
A11: Current week (by date) | B11: =MAX(1,MIN(64,INT(($B$8-$B$5)/7)+1)) -> 1 | D11: Proposals sent | E11: =COUNTA('Upwork Pipeline'!$A$6:$A$505) -> 0
A12: Weeks marked Done | B12: =COUNTIF('Weekly Plan'!$G$5:$G$68,"Done") -> 1 | D12: Connects spent | E12: =SUM('Upwork Pipeline'!$F$6:$F$505) -> 0
A13: Weeks completed % | B13: =B12/64 -> 0.015625 | D13: Viewed | E13: =COUNTIF('Upwork Pipeline'!$I$6:$I$505,"Yes") -> 0
A14: Weeks behind schedule | B14: =MAX(0,COUNTIFS('Weekly Plan'!$B$5:$B$68,"<"&$B$8-6,'Weekly Plan'!$G$5:$G$68,"<>Done")) -> 0 | D14: Interviews | E14: =COUNTIF('Upwork Pipeline'!$J$6:$J$505,"Yes") -> 0
A15: Planned hours to date | B15: =SUMIFS('Weekly Plan'!$E$5:$E$68,'Weekly Plan'!$A$5:$A$68,"<="&B11) -> 20 | D15: Hired | E15: =COUNTIF('Upwork Pipeline'!$K$6:$K$505,"Yes") -> 0
A16: Actual hours logged | B16: =SUM('Weekly Plan'!$F$5:$F$68) -> 20 | D16: Win rate (hired / sent) | E16: =IF(E11=0,0,E15/E11) -> 0
A17: Hours vs plan | B17: =IF(B15=0,0,B16/B15) -> 1 | D17: Total contract value ($) | E17: =SUM('Upwork Pipeline'!$L$6:$L$505) -> 0
A18: Projects done (of 14) | B18: =COUNTIF(Projects!$E$5:$E$18,"Done") -> 0 | D18: Average hourly rate on hires ($) | E18: =IFERROR(AVERAGEIFS('Upwork Pipeline'!$G$6:$G$505,'Upwork Pipeline'!$K$6:$K$505,"Yes",'Upwork Pipeline'!$E$6:$E$505,"Hourly"),0) -> 0
A19: Case studies written | B19: =COUNTIF(Projects!$I$5:$I$18,"Yes") -> 0 | D19: Last logged month income ($) | E19: =IFERROR(INDEX('Monthly Review'!$H$5:$H$20,MATCH(9.99E+307,'Monthly Review'!$H$5:$H$20)),0) -> 900
A20: Average confidence (1–5) | B20: =IFERROR(AVERAGE('Weekly Plan'!$H$5:$H$68),0) -> 4 | D20: Progress to income goal | E20: =IF($B$7=0,0,E19/$B$7) -> 0.18
A21: Skills at target | B21: =COUNTIF(Skills!$H$5:$H$50,"At target") -> 0
A24: Phases
A25: Phase | B25: % done | D25: Weeks done | E25: Weeks in phase
A26: 1. Foundations & bridge from DBA | B26: =IF(E26=0,0,D26/E26) -> 0.16666667 | D26: =COUNTIFS('Weekly Plan'!$C$5:$C$68,1,'Weekly Plan'!$G$5:$G$68,"Done") -> 1 | E26: =COUNTIF('Weekly Plan'!$C$5:$C$68,1) -> 6
A27: 2. Warehouses + dbt in depth | B27: =IF(E27=0,0,D27/E27) -> 0 | D27: =COUNTIFS('Weekly Plan'!$C$5:$C$68,2,'Weekly Plan'!$G$5:$G$68,"Done") -> 0 | E27: =COUNTIF('Weekly Plan'!$C$5:$C$68,2) -> 11
A28: 3. BI & business analytics | B28: =IF(E28=0,0,D28/E28) -> 0 | D28: =COUNTIFS('Weekly Plan'!$C$5:$C$68,3,'Weekly Plan'!$G$5:$G$68,"Done") -> 0 | E28: =COUNTIF('Weekly Plan'!$C$5:$C$68,3) -> 7
A29: 4. Batch ELT deployed on AWS | B29: =IF(E29=0,0,D29/E29) -> 0 | D29: =COUNTIFS('Weekly Plan'!$C$5:$C$68,4,'Weekly Plan'!$G$5:$G$68,"Done") -> 0 | E29: =COUNTIF('Weekly Plan'!$C$5:$C$68,4) -> 11
A30: 5. Streaming & AWS lakehouse | B30: =IF(E30=0,0,D30/E30) -> 0 | D30: =COUNTIFS('Weekly Plan'!$C$5:$C$68,5,'Weekly Plan'!$G$5:$G$68,"Done") -> 0 | E30: =COUNTIF('Weekly Plan'!$C$5:$C$68,5) -> 11
A31: 6. Client-ready specialization | B31: =IF(E31=0,0,D31/E31) -> 0 | D31: =COUNTIFS('Weekly Plan'!$C$5:$C$68,6,'Weekly Plan'!$G$5:$G$68,"Done") -> 0 | E31: =COUNTIF('Weekly Plan'!$C$5:$C$68,6) -> 11
A32: 7. Capstone, certification & launch | B32: =IF(E32=0,0,D32/E32) -> 0 | D32: =COUNTIFS('Weekly Plan'!$C$5:$C$68,7,'Weekly Plan'!$G$5:$G$68,"Done") -> 0 | E32: =COUNTIF('Weekly Plan'!$C$5:$C$68,7) -> 7
A35: How to use
A36: • Yellow cells are inputs. White cells are formulas: leave them alone.
A37: • Every Sunday: in Weekly Plan, enter actual hours, set Status, rate confidence 1–5, add notes.
A38: • Every proposal: add one row in Upwork Pipeline.
A39: • End of each month: fill income and reflections in Monthly Review, and re-rate yourself in Skills.
A40: • Row 5 of Upwork Pipeline and Projects is an example of the expected format; overwrite or delete it.

Sheet Weekly Plan
A1: Weekly Plan — 64 weeks
A2: Dates follow the start date on the Dashboard. Fill the yellow columns each Sunday.
A4: Week | B4: Start | C4: Phase | D4: Focus | E4: Planned h | F4: Actual h | G4: Status | H4: Confidence (1–5) | I4: Project | J4: Learn | K4: Build | L4: Upwork action | M4: Notes / blockers
A5: 1 | B5: =Dashboard!$B$5+(A5-1)*7 -> 46293 | C5: 1 | D5: Advanced analytical SQL I | E5: 20 | F5: 20 | G5: Done | H5: 4 | J5: Window functions (ROW_NUMBER, RANK, LAG/LEAD, running totals), CTEs, QUALIFY, GROUPING SETS/ROLLUP, CASE-based pivots. Install DuckDB and practice locally for free. | K5: Solve 30 analytical SQL exercises on a sample dataset; push to a GitHub repo 'sql-analytics-practice'. | L5: Audit your current profile. List the past DBA/DevOps jobs that support an analytics story (SQL tuning, MySQL, Docker, Linux). | M5: Example row: replace with your own. Window functions solid; GROUPING SETS needs review.
A6: 2 | B6: =Dashboard!$B$5+(A6-1)*7 -> 46300 | C6: 1 | D6: Advanced analytical SQL II | E6: 20 | G6: Not started | J6: Analytics patterns: cohorts, retention, funnels, sessionization, gaps-and-islands, date spines, deduplication, percentiles. Reading query plans in a columnar engine vs MySQL. | K6: Add 20 pattern exercises with written explanations to the practice repo. | L6: Save 20 real analytics engineer / dbt / Snowflake job posts to a research list. Note tools, budgets and wording.
A7: 3 | B7: =Dashboard!$B$5+(A7-1)*7 -> 46307 | C7: 1 | D7: Dimensional modeling (Kimball) | E7: 20 | G7: Not started | I7: P1 | J7: Grain, fact types (transaction, periodic snapshot, accumulating), conformed dimensions, surrogate keys, SCD types 1/2, bus matrix, one-big-table vs star schema. | K7: P1 starts: design a bus matrix and star schema for the MySQL Sakila sample database. | L7: Summarize the 20 saved posts: top 10 recurring requirements. Adjust the plan if something big is missing.
A8: 4 | B8: =Dashboard!$B$5+(A8-1)*7 -> 46314 | C8: 1 | D8: Python for data work | E8: 20 | G8: Not started | J8: pandas or polars basics, requests, API pagination and retries, environment variables and secrets, logging, pytest, project structure with virtual environments. | K8: Python extractor exercise: a public REST API to Parquet files, with tests and logging. | L8: Keep taking DBA/DevOps work for income. No new-niche bids yet.
A9: 5 | B9: =Dashboard!$B$5+(A9-1)*7 -> 46321 | C9: 1 | D9: dbt fundamentals | E9: 20 | G9: Not started | I9: P1 | J9: dbt-duckdb setup, project structure (staging / intermediate / marts), sources, ref, materializations, generic tests, docs, seeds. Complete the free dbt Fundamentals course. | K9: P1: staging and intermediate models for Sakila in dbt on DuckDB. | L9: Draft a new headline and overview that bridge 'MySQL DBA' to 'data warehouse / analytics'.
A10: 6 | B10: =Dashboard!$B$5+(A10-1)*7 -> 46328 | C10: 1 | D10: Project 1 delivery | E10: 20 | G10: Not started | I10: P1 | J10: Metabase basics (run in Docker), writing a project README, drawing a simple architecture diagram. | K10: P1 finish: fact and dimension marts, tests, dbt docs, Metabase dashboard, README with business story. | L10: Add P1 to your portfolio. Update your profile with the bridge headline.
A11: 7 | B11: =Dashboard!$B$5+(A11-1)*7 -> 46335 | C11: 2 | D11: Snowflake architecture | E11: 20 | G11: Not started | I11: P2 | J11: Virtual warehouses, micro-partitions, RBAC and roles, stages, file formats, COPY INTO, time travel, zero-copy cloning, credit usage, resource monitors, auto-suspend. | K11: Start the Snowflake free trial. On day one set Snowflake resource monitors and an AWS Budgets alarm on your AWS account. Load the Olist CSVs through a stage with COPY INTO. Script your roles and warehouses. | L11: Take the Snowflake-related Upwork skill tags into your profile once you have used them.
A12: 8 | B12: =Dashboard!$B$5+(A12-1)*7 -> 46342 | C12: 2 | D12: dbt intermediate | E12: 20 | G12: Not started | I12: P2 | J12: Incremental models (merge strategy, is_incremental), snapshots for SCD2, Jinja and macros, packages (dbt_utils, dbt_expectations), exposures. | K12: P2: staging and intermediate models for Olist on Snowflake. | L12: Read 10 winning-style proposals in the analytics category (profiles of top freelancers) and note their structure.
A13: 9 | B13: =Dashboard!$B$5+(A13-1)*7 -> 46349 | C13: 2 | D13: Project 2: marts & tests | E13: 20 | G13: Not started | I13: P2 | J13: Designing marts for business questions, naming conventions, test coverage strategy. | K13: P2: fct_orders, fct_order_items, dim_customers, dim_sellers, dim_products, dim_date with tests. | L13: Write 3 proposal templates: dbt fix, SQL optimization, dashboard + model.
A14: 10 | B14: =Dashboard!$B$5+(A14-1)*7 -> 46356 | C14: 2 | D14: Project 2: metrics & dashboard | E14: 20 | G14: Not started | I14: P2 | J14: Metric definitions (revenue, AOV, delivery SLA, repeat rate), Metabase questions and dashboards. | K14: P2: first dashboard in Metabase for revenue, delivery performance, seller performance and review score vs delay (rebuilt properly in Power BI in P4). Publish dbt docs. | L14: Prepare the specialized profile text: 'Analytics Engineer | Snowflake + dbt'.
A15: 11 | B15: =Dashboard!$B$5+(A15-1)*7 -> 46363 | C15: 2 | D15: CI/CD for dbt | E15: 20 | G15: Not started | I15: P2 | J15: GitHub Actions for dbt build on pull requests, slim CI with state:modified, separate dev and prod targets, pre-commit and SQLFluff linting. | K15: P2 finish: CI pipeline, README, one-page case study. | L15: Publish the specialized profile. Start 2–3 proposals per week on small dbt/SQL/dashboard jobs.
A16: 12 | B16: =Dashboard!$B$5+(A16-1)*7 -> 46370 | C16: 2 | D16: BigQuery fundamentals | E16: 20 | G16: Not started | I16: P3 | J16: Storage vs compute, partitioning and clustering, on-demand pricing (bytes scanned), nested fields (STRUCT, ARRAY, UNNEST), the free sandbox. GCP basics: projects, IAM, service accounts, Cloud Storage, billing budgets. | K16: Explore the public GA4 sample dataset (bigquery-public-data.ga4_obfuscated_sample_ecommerce). | L16: 3 proposals. Track every one in the Upwork Pipeline sheet.
A17: 13 | B17: =Dashboard!$B$5+(A17-1)*7 -> 46377 | C17: 2 | D17: Project 3: GA4 modeling | E17: 20 | G17: Not started | I17: P3 | J17: GA4 event schema, flattening event_params, sessionization, channel grouping, funnels. | K17: P3: dbt-bigquery project with sessions, events and funnel models. | L17: 3 proposals. Prefer fixed-price jobs under $300 for fast reviews.
A18: 14 | B18: =Dashboard!$B$5+(A18-1)*7 -> 46384 | C18: 2 | D18: Project 3: Looker Studio dashboard | E18: 20 | G18: Not started | I18: P3 | J18: Looker Studio: data sources on BigQuery, calculated fields, filters and controls, blending, sharing. Measuring bytes scanned before and after partitioning. | K18: P3: marketing funnel dashboard in Looker Studio, cost notes on partitioning. | L18: Add P2 to the portfolio. 3 proposals.
A19: 15 | B19: =Dashboard!$B$5+(A19-1)*7 -> 46391 | C19: 2 | D19: Project 3: deploy on Google Cloud | E19: 20 | G19: Not started | I19: P3 | J19: Cloud Run jobs, Cloud Scheduler, Secret Manager, Artifact Registry, service accounts with least privilege. | K19: P3 finish: dbt packaged in a container, run daily as a Cloud Run job on Cloud Scheduler with Secret Manager. README, case study. | L19: Add P3 to the portfolio. 3 proposals.
A20: 16 | B20: =Dashboard!$B$5+(A20-1)*7 -> 46398 | C20: 2 | D20: Data quality & dbt testing | E20: 20 | G20: Not started | J20: Singular and generic tests, dbt unit tests, model contracts, source freshness, intro to the dbt Semantic Layer. | K20: Add unit tests, contracts and freshness checks to P2. | L20: 3–5 proposals. Follow up on any viewed proposals.
A21: 17 | B21: =Dashboard!$B$5+(A21-1)*7 -> 46405 | C21: 2 | D21: Review & buffer | E21: 15 | G21: Not started | J21: Catch up on anything behind. Review weak spots from the Skills sheet. | K21: Clean GitHub, write a GitHub profile README that links all projects. Mid-phase retrospective. | L21: Review proposal stats: views, replies, interviews. Improve the weakest template.
A22: 18 | B22: =Dashboard!$B$5+(A22-1)*7 -> 46412 | C22: 3 | D22: Power BI fundamentals | E22: 20 | G22: Not started | I22: P4 | J22: Power BI Desktop, Power Query, star-schema data model, relationships, Import vs DirectQuery, connecting to Snowflake and BigQuery, publishing to the Power BI Service (use the free trial). | K22: Connect Power BI to your P2 Snowflake marts; build the model on top of dbt facts and dimensions (no transformations in Power BI). | L22: 3–5 proposals. Start including small "Power BI dashboard" jobs.
A23: 19 | B23: =Dashboard!$B$5+(A23-1)*7 -> 46419 | C23: 3 | D23: DAX essentials | E23: 20 | G23: Not started | I23: P4 | J23: Measures vs calculated columns, CALCULATE and filter context, a proper date table, time intelligence (YTD, MoM, YoY), ranking, basic performance rules. | K23: Write the measures for P4: revenue, orders, AOV, growth %, repeat-customer rate, delivery SLA. | L23: 3–5 proposals.
A24: 20 | B24: =Dashboard!$B$5+(A24-1)*7 -> 46426 | C24: 3 | D24: Dashboard design & storytelling | E24: 20 | G24: Not started | I24: P4 | J24: Chart choice, KPI cards, layout for executives vs analysts, color and accessibility, drill-through, tooltips, mobile layout. Read "Storytelling with Data" (Knaflic). | K24: Sketch the P4 pages on paper first: executive overview, products, customers, delivery. | L24: 3–5 proposals. Save 10 good dashboard examples from Upwork portfolios.
A25: 21 | B25: =Dashboard!$B$5+(A25-1)*7 -> 46433 | C25: 3 | D25: Project 4: sales analytics in Power BI | E25: 20 | G25: Not started | I25: P4 | J25: Sales KPIs: revenue, AOV, product and category mix, RFM customer segments, cohorts, geography. Row-level security, scheduled refresh. | K25: P4 finish: multi-page Power BI sales dashboard on Snowflake with row-level security per seller, scheduled refresh, 3-minute demo video, case study. | L25: Add P4 to portfolio. Create a "Power BI on Snowflake/BigQuery" specialized profile section.
A26: 22 | B26: =Dashboard!$B$5+(A26-1)*7 -> 46440 | C26: 3 | D26: Marketing analytics domain | E26: 20 | G26: Not started | I26: P5 | J26: Ad platform data (Google Ads, Meta Ads), UTM parameters, CAC, ROAS, CPA, attribution models (last-click, first-click, linear), blended vs platform-reported numbers. | K26: P5 starts: generate realistic Google/Meta ad-spend data by campaign and day matching the GA4 sample dates; load to BigQuery; dbt staging. | L26: 3–5 proposals. Look at marketing-agency job posts and note what they measure.
A27: 23 | B27: =Dashboard!$B$5+(A27-1)*7 -> 46447 | C27: 3 | D27: Project 5: marketing performance | E27: 20 | G27: Not started | I27: P5 | J27: Joining sessions, orders and ad spend by channel and campaign; handling attribution windows; one source of truth vs ad platform numbers. | K27: P5 finish: dbt marts for campaign performance, Looker Studio dashboard (ROAS, CAC, spend vs revenue by channel), plus a Power BI version of the executive page. Case study. | L27: Add P5 to portfolio. Draft a fixed-price "marketing dashboard" offer.
A28: 24 | B28: =Dashboard!$B$5+(A28-1)*7 -> 46454 | C28: 3 | D28: BI review & offers | E28: 15 | G28: Not started | J28: Review weak DAX topics. Power BI performance basics (aggregations, reducing model size). | K28: Polish P4 and P5 screenshots and videos. Retrospective. | L28: Publish two Project Catalog offers: "Power BI sales dashboard" and "Marketing performance dashboard". Review proposal stats.
A29: 25 | B29: =Dashboard!$B$5+(A29-1)*7 -> 46461 | C29: 4 | D29: Ingestion with Airbyte | E29: 20 | G29: Not started | J29: Self-hosting Airbyte on EC2 with Docker, connectors, sync modes (full refresh, incremental append, incremental dedup), CDC concepts. Fivetran concepts and pricing model. | K29: Airbyte on an EC2 instance (Docker), syncing MySQL/Postgres into Snowflake. | L29: 3–5 proposals. Include 'Airbyte / ELT setup' jobs where your DevOps skills help.
A30: 26 | B30: =Dashboard!$B$5+(A30-1)*7 -> 46468 | C30: 4 | D30: Custom extractors with dlt | E30: 20 | G30: Not started | J30: dlt (data load tool): REST sources, pagination, rate limits, incremental cursors, schema evolution, secrets handling. | K30: dlt pipeline from a public API into Snowflake with incremental loading. | L30: 3–5 proposals.
A31: 27 | B31: =Dashboard!$B$5+(A31-1)*7 -> 46475 | C31: 4 | D31: Project 4: SaaS data ingestion | E31: 20 | G31: Not started | I31: P6 | J31: Stripe data model (customers, subscriptions, invoices), CRM data basics. | K31: P6: generate Stripe test-mode data with a script, plus CRM and targets data; load all into Snowflake with dlt/Airbyte. | L31: 3–5 proposals.
A32: 28 | B32: =Dashboard!$B$5+(A32-1)*7 -> 46482 | C32: 4 | D32: Project 4: SaaS metrics | E32: 20 | G32: Not started | I32: P6 | J32: MRR, churn, expansion, contraction, cohort retention, LTV definitions. | K32: P6 finish: dbt metric models, Power BI SaaS dashboard (MRR bridge, churn, cohort retention heatmap), README, case study. | L32: Add P6 to portfolio. 3–5 proposals.
A33: 29 | B33: =Dashboard!$B$5+(A33-1)*7 -> 46489 | C33: 4 | D33: Orchestration with Airflow | E33: 20 | G33: Not started | J33: DAGs, operators, TaskFlow API, scheduling, retries, connections, Astronomer Cosmos for dbt. Deployment options on AWS: Airflow on EC2/ECS vs Amazon MWAA (managed, costs more). Dagster at a concept level. | K33: Airflow running P6 end to end on a daily schedule, locally first, ready to move to AWS in week 32. | L33: 3–5 proposals. Airflow setup jobs are a good bridge from DevOps.
A34: 30 | B34: =Dashboard!$B$5+(A34-1)*7 -> 46496 | C34: 4 | D34: AWS for data engineering | E34: 20 | G34: Not started | J34: Refresh from your Cloud Practitioner/SA study, applied to data: IAM roles and least privilege, S3 layouts and lifecycle rules, VPC and security groups, Secrets Manager, Lambda, ECS Fargate, CloudWatch logs and alarms, SNS. | K34: Hands-on: S3 buckets, IAM roles, a Lambda that lands API data in S3, CloudWatch alarm to SNS email. Budget alarm checked. | L34: 3–5 proposals. Add AWS data skills to your profile; your Cloud Practitioner certificate supports them.
A35: 31 | B35: =Dashboard!$B$5+(A35-1)*7 -> 46503 | C35: 4 | D35: Terraform for AWS data infrastructure | E35: 20 | G35: Not started | J35: Terraform AWS provider, modules, remote state in S3, variables per environment, terraform destroy discipline. | K35: Terraform module: S3 data buckets, IAM role for a Snowflake storage integration, SQS event notification for Snowpipe auto-ingest, Secrets Manager entries, budget alarm. | L35: 3–5 proposals.
A36: 32 | B36: =Dashboard!$B$5+(A36-1)*7 -> 46510 | C36: 4 | D36: Project 7: pipeline deployed on AWS | E36: 20 | G36: Not started | I36: P7 | J36: Idempotent loads, backfills, incremental models on large tables. Running Airflow on AWS: ECS Fargate or EC2 for the portfolio, MWAA briefly for a demo then destroy it. | K36: P7: monthly NYC TLC Parquet files → S3 → Snowpipe → Snowflake → dbt incremental models, orchestrated by Airflow running on AWS, all created with Terraform. | L36: 3–5 proposals.
A37: 33 | B37: =Dashboard!$B$5+(A37-1)*7 -> 46517 | C37: 4 | D37: Project 5 delivery | E37: 20 | G37: Not started | I37: P7 | J37: CloudWatch alarms and SNS/Slack alerts on failure, rerun safety, cost per run, terraform destroy and recreate. | K37: P7 finish: backfill of 12+ months, alerts, Power BI operations dashboard (trips, revenue, zones), AWS architecture diagram, monthly cost estimate, README, case study. | L37: Add P7 to portfolio as "production pipeline on AWS". 3–5 proposals.
A38: 34 | B38: =Dashboard!$B$5+(A38-1)*7 -> 46524 | C38: 4 | D38: Project 6: MySQL → Snowflake migration | E38: 20 | G38: Not started | I38: P8 | J38: Schema and data type mapping, initial load strategies, incremental sync, reconciliation (row counts, checksums, aggregates). AWS DMS at a concept level. | K38: P8: migrate a realistic MySQL database running on Amazon RDS into Snowflake (Sakila scaled up or the MySQL employees sample). | L38: Draft a fixed-price offer: 'MySQL to Snowflake/BigQuery migration'. It uses your existing reviews.
A39: 35 | B39: =Dashboard!$B$5+(A39-1)*7 -> 46531 | C39: 4 | D39: Project 6 delivery + mid-year review | E39: 20 | G39: Not started | I39: P8 | J39: Cutover planning, runbooks, validation reports. | K39: P8 finish: cutover runbook, validation report, cost comparison, case study. | L39: Publish the migration offer in the Project Catalog ("MySQL / RDS to Snowflake"). Mid-year review of rate and win rate.
A40: 36 | B40: =Dashboard!$B$5+(A40-1)*7 -> 46538 | C40: 5 | D40: Kafka fundamentals | E40: 20 | G40: Not started | J40: Topics, partitions, consumer groups, offsets, delivery semantics. Run Kafka or Redpanda in Docker. Python producers and consumers. | K40: Producer/consumer exercise with an order-event generator. | L40: 3–5 proposals. Keep 1 active client if possible.
A41: 37 | B41: =Dashboard!$B$5+(A41-1)*7 -> 46545 | C41: 5 | D41: CDC with Debezium | E41: 20 | G41: Not started | I41: P9 | J41: MySQL binlog configuration (your strength), Kafka Connect, Debezium MySQL connector, schema registry basics. | K41: Debezium capturing inserts, updates and deletes from MySQL into Kafka topics. | L41: 3–5 proposals.
...

Sheet Projects
A1: Portfolio Projects
A2: One row per project. Planned weeks and stack come from the roadmap; the yellow columns are yours.
A4: ID | B4: Project | C4: Planned weeks | D4: Stack | E4: Status | F4: Started | G4: Finished | H4: GitHub link | I4: Case study | J4: On Upwork portfolio | K4: Key result (with a number) | L4: Done when
A5: P1 | B5: Sakila: from MySQL to a star schema | C5: 3–6 | D5: MySQL, DuckDB, dbt-duckdb, Metabase (Docker) | E5: In progress | F5: 46307 | H5: github.com/your-user/sakila-analytics | I5: No | J5: No | K5: Example: dashboard answers 5 questions; 42 dbt tests passing | L5: dbt build passes with tests on every primary key; dashboard answers 5 business questions
A6: P2 | B6: Olist marketplace analytics on Snowflake | C6: 7–11, 16 | D6: Snowflake, dbt Core, GitHub Actions, SQLFluff, Metabase | E6: Not started | I6: No | J6: No | L6: CI runs on every pull request; dashboard shows revenue, AOV, delivery SLA, seller scores
A7: P3 | B7: GA4 marketing analytics on BigQuery (Google Cloud) | C7: 12–15 | D7: BigQuery, dbt-bigquery, Looker Studio, Docker, Cloud Run jobs, Cloud Scheduler, Secret Manager | E7: Not started | I7: No | J7: No | L7: Funnel from session to purchase by channel; dbt runs daily in Cloud Run without your laptop; documented bytes-scanned savings
A8: P4 | B8: Sales analytics dashboard in Power BI | C8: 18–21 | D8: Power BI Desktop and Service, DAX, Snowflake connector, row-level security, scheduled refresh | E8: Not started | I8: No | J8: No | L8: A non-technical person can answer 5 business questions from it in under a minute; refresh runs on schedule
A9: P5 | B9: Marketing performance dashboard | C9: 22–23 | D9: BigQuery, dbt, Looker Studio, Power BI | E9: Not started | I9: No | J9: No | L9: Spend, sessions and revenue reconcile by channel and day; dashboard ranks campaigns by ROAS
A10: P6 | B10: SaaS revenue metrics (MRR, churn, LTV) | C10: 27–28 | D10: Python, dlt, Airbyte, Snowflake, dbt, Airflow, Power BI | E10: Not started | I10: No | J10: No | L10: MRR bridge (new, expansion, contraction, churn) reconciles to raw invoices
A11: P7 | B11: NYC Taxi pipeline deployed on AWS | C11: 32–33 | D11: Terraform, S3, SQS + Snowpipe, Snowflake, dbt incremental, Airflow on ECS Fargate/EC2 (MWAA demo), CloudWatch, SNS alerts | E11: Not started | I11: No | J11: No | L11: terraform apply creates everything from scratch; reruns are idempotent; a failed run sends an alert
A12: P8 | B12: MySQL to Snowflake migration | C12: 34–35 | D12: Amazon RDS for MySQL, Airbyte or dlt, Snowflake, Python reconciliation scripts | E12: Not started | I12: No | J12: No | L12: Row counts and checksums match for every table; runbook tested once end to end
A13: P9 | B13: Real-time orders with CDC | C13: 37–40 | D13: MySQL binlog, Debezium, Kafka/Redpanda, Snowflake Kafka connector, Dynamic Tables, dbt | E13: Not started | I13: No | J13: No | L13: Inserts, updates and deletes appear in Snowflake within target latency; replay after failure works
A14: P10 | B14: Serverless lakehouse on AWS (Glue, Athena, Iceberg) | C14: 42–44 | D14: PySpark, AWS Glue jobs and Data Catalog, S3, Apache Iceberg, Athena, Step Functions or Airflow, Terraform | E14: Not started | I14: No | J14: No | L14: Glue jobs run on the full dataset; Athena queries use partition pruning; costs documented
A15: P11 | B15: Warehouse cost audit | C15: 47–48 | D15: Snowflake query history, query profile, resource monitors, dbt | E15: Not started | I15: No | J15: No | L15: Measured cost reduction with evidence for each change
A16: P12 | B16: E-commerce analytics starter kit | C16: 50–51 | D16: Shopify API, dlt, Snowflake or BigQuery, dbt template, Power BI template (.pbit), Looker Studio template | E16: Not started | I16: No | J16: No | L16: A new store can be set up from the template in one day
A17: P13 | B17: Redshift on AWS | C17: 53 | D17: Redshift Serverless, Redshift Spectrum, S3, dbt-redshift, Terraform | E17: Not started | I17: No | J17: No | L17: dbt build passes on Redshift with the same tests as P2
A18: P14 | B18: Capstone: modern data platform on AWS | C18: 58–62 | D18: Terraform, AWS (S3, ECS/MWAA, Secrets Manager, CloudWatch), Snowflake, dlt/Airbyte, Debezium/Kafka, dbt, Airflow, GitHub Actions with OIDC, Elementary, Power BI | E18: Not started | I18: No | J18: No | L18: Someone else could run it from your README; video explains business value in plain words

Sheet Skills
A1: Skills Self-Assessment
A2: Rate yourself 1–5 at the end of each quarter (1 = never used, 3 = can do with docs, 5 = could teach it).
A4: Area | B4: Skill | C4: Target | D4: Check 1 (wk 16) | E4: Check 2 (wk 32) | F4: Check 3 (wk 48) | G4: Check 4 (wk 64) | H4: Status | I4: Evidence (project / link)
A5: SQL | B5: Window functions & analytical patterns | C5: 5 | H5: =IF(COUNT(D5:G5)=0,"Not rated",IF(IF(G5<>"",G5,IF(F5<>"",F5,IF(E5<>"",E5,D5)))>=C5,"At target","Below target")) -> Not rated
A6: SQL | B6: Query performance in columnar warehouses | C6: 4 | H6: =IF(COUNT(D6:G6)=0,"Not rated",IF(IF(G6<>"",G6,IF(F6<>"",F6,IF(E6<>"",E6,D6)))>=C6,"At target","Below target")) -> Not rated
A7: Modeling | B7: Kimball dimensional modeling | C7: 5 | H7: =IF(COUNT(D7:G7)=0,"Not rated",IF(IF(G7<>"",G7,IF(F7<>"",F7,IF(E7<>"",E7,D7)))>=C7,"At target","Below target")) -> Not rated
A8: Modeling | B8: SCD & snapshots | C8: 4 | H8: =IF(COUNT(D8:G8)=0,"Not rated",IF(IF(G8<>"",G8,IF(F8<>"",F8,IF(E8<>"",E8,D8)))>=C8,"At target","Below target")) -> Not rated
A9: Python | B9: pandas / polars | C9: 4 | H9: =IF(COUNT(D9:G9)=0,"Not rated",IF(IF(G9<>"",G9,IF(F9<>"",F9,IF(E9<>"",E9,D9)))>=C9,"At target","Below target")) -> Not rated
A10: Python | B10: API extraction, pagination, retries | C10: 4 | H10: =IF(COUNT(D10:G10)=0,"Not rated",IF(IF(G10<>"",G10,IF(F10<>"",F10,IF(E10<>"",E10,D10)))>=C10,"At target","Below target")) -> Not rated
A11: Python | B11: Testing with pytest | C11: 3 | H11: =IF(COUNT(D11:G11)=0,"Not rated",IF(IF(G11<>"",G11,IF(F11<>"",F11,IF(E11<>"",E11,D11)))>=C11,"At target","Below target")) -> Not rated
A12: dbt | B12: Models, sources, refs, materializations | C12: 5 | H12: =IF(COUNT(D12:G12)=0,"Not rated",IF(IF(G12<>"",G12,IF(F12<>"",F12,IF(E12<>"",E12,D12)))>=C12,"At target","Below target")) -> Not rated
A13: dbt | B13: Incremental models | C13: 5 | H13: =IF(COUNT(D13:G13)=0,"Not rated",IF(IF(G13<>"",G13,IF(F13<>"",F13,IF(E13<>"",E13,D13)))>=C13,"At target","Below target")) -> Not rated
A14: dbt | B14: Macros & Jinja | C14: 4 | H14: =IF(COUNT(D14:G14)=0,"Not rated",IF(IF(G14<>"",G14,IF(F14<>"",F14,IF(E14<>"",E14,D14)))>=C14,"At target","Below target")) -> Not rated
A15: dbt | B15: Tests, unit tests, contracts | C15: 5 | H15: =IF(COUNT(D15:G15)=0,"Not rated",IF(IF(G15<>"",G15,IF(F15<>"",F15,IF(E15<>"",E15,D15)))>=C15,"At target","Below target")) -> Not rated
A16: dbt | B16: CI/CD with GitHub Actions | C16: 4 | H16: =IF(COUNT(D16:G16)=0,"Not rated",IF(IF(G16<>"",G16,IF(F16<>"",F16,IF(E16<>"",E16,D16)))>=C16,"At target","Below target")) -> Not rated
... A50: Business | B50: SaaS metrics (MRR, churn, cohorts) | C50: 4 | H50: =IF(COUNT(D50:G50)=0,"Not rated",IF(IF(G50<>"",G50,IF(F50<>"",F50,IF(E50<>"",E50,D50)))>=C50,"At target","Below target")) -> Not rated

Sheet Upwork Pipeline
A1: Upwork Pipeline
A2: One row per proposal. Row 5 is an example of the format; start your entries from row 6.
A4: Date sent | B4: Job title | C4: Client country | D4: Category | E4: Type | F4: Connects | G4: Rate / budget ($) | H4: Template used | I4: Viewed | J4: Interview | K4: Hired | L4: Contract value ($) | M4: Notes
A5: 46368 | B5: Build dbt models on Snowflake for Shopify data | C5: USA | D5: dbt / Snowflake | E5: Fixed | F5: 16 | G5: 250 | H5: dbt fix | I5: Yes | J5: Yes | K5: No | L5: 0 | M5: Example row. Client chose a cheaper bid.

Sheet Monthly Review
A1: Monthly Review
A2: Month columns are calculated from the start date. Proposals and hours are pulled automatically; income and reflections are yours.
A4: Month # | B4: Month starting | C4: Weeks done | D4: Hours logged | E4: Proposals | F4: Hires | G4: Niche income ($) | H4: Total freelance income ($) | I4: Current rate ($/hr) | J4: What worked | K4: What to change next month
A5: 1 | B5: =DATE(YEAR(Dashboard!$B$5),MONTH(Dashboard!$B$5)+A5-1,1) -> 46266 | C5: =COUNTIFS('Weekly Plan'!$B$5:$B$68,">="&B5,'Weekly Plan'!$B$5:$B$68,"<"&DATE(YEAR(Dashboard!$B$5),MONTH(Dashboard!$B$5)+A5,1),'Weekly Plan'!$G$5:$G$68,"Done") -> 1 | D5: =SUMIFS('Weekly Plan'!$F$5:$F$68,'Weekly Plan'!$B$5:$B$68,">="&B5,'Weekly Plan'!$B$5:$B$68,"<"&DATE(YEAR(Dashboard!$B$5),MONTH(Dashboard!$B$5)+A5,1)) -> 20 | E5: =COUNTIFS('Upwork Pipeline'!$A$6:$A$505,">="&B5,'Upwork Pipeline'!$A$6:$A$505,"<"&DATE(YEAR(Dashboard!$B$5),MONTH(Dashboard!$B$5)+A5,1)) -> 0 | F5: =COUNTIFS('Upwork Pipeline'!$A$6:$A$505,">="&B5,'Upwork Pipeline'!$A$6:$A$505,"<"&DATE(YEAR(Dashboard!$B$5),MONTH(Dashboard!$B$5)+A5,1),'Upwork Pipeline'!$K$6:$K$505,"Yes") -> 0 | G5: 0 | H5: 900 | I5: 20 | J5: Example: finished P1 on time; DBA contract covered costs.
A6: 2 | B6: =DATE(YEAR(Dashboard!$B$5),MONTH(Dashboard!$B$5)+A6-1,1) -> 46296 | C6: =COUNTIFS('Weekly Plan'!$B$5:$B$68,">="&B6,'Weekly Plan'!$B$5:$B$68,"<"&DATE(YEAR(Dashboard!$B$5),MONTH(Dashboard!$B$5)+A6,1),'Weekly Plan'!$G$5:$G$68,"Done") -> 0 | D6: =SUMIFS('Weekly Plan'!$F$5:$F$68,'Weekly Plan'!$B$5:$B$68,">="&B6,'Weekly Plan'!$B$5:$B$68,"<"&DATE(YEAR(Dashboard!$B$5),MONTH(Dashboard!$B$5)+A6,1)) -> 0 | E6: =COUNTIFS('Upwork Pipeline'!$A$6:$A$505,">="&B6,'Upwork Pipeline'!$A$6:$A$505,"<"&DATE(YEAR(Dashboard!$B$5),MONTH(Dashboard!$B$5)+A6,1)) -> 0 | F6: =COUNTIFS('Upwork Pipeline'!$A$6:$A$505,">="&B6,'Upwork Pipeline'!$A$6:$A$505,"<"&DATE(YEAR(Dashboard!$B$5),MONTH(Dashboard!$B$5)+A6,1),'Upwork Pipeline'!$K$6:$K$505,"Yes") -> 0
A7: 3 | B7: =DATE(YEAR(Dashboard!$B$5),MONTH(Dashboard!$B$5)+A7-1,1) -> 46327 | C7: =COUNTIFS('Weekly Plan'!$B$5:$B$68,">="&B7,'Weekly Plan'!$B$5:$B$68,"<"&DATE(YEAR(Dashboard!$B$5),MONTH(Dashboard!$B$5)+A7,1),'Weekly Plan'!$G$5:$G$68,"Done") -> 0 | D7: =SUMIFS('Weekly Plan'!$F$5:$F$68,'Weekly Plan'!$B$5:$B$68,">="&B7,'Weekly Plan'!$B$5:$B$68,"<"&DATE(YEAR(Dashboard!$B$5),MONTH(Dashboard!$B$5)+A7,1)) -> 0 | E7: =COUNTIFS('Upwork Pipeline'!$A$6:$A$505,">="&B7,'Upwork Pipeline'!$A$6:$A$505,"<"&DATE(YEAR(Dashboard!$B$5),MONTH(Dashboard!$B$5)+A7,1)) -> 0 | F7: =COUNTIFS('Upwork Pipeline'!$A$6:$A$505,">="&B7,'Upwork Pipeline'!$A$6:$A$505,"<"&DATE(YEAR(Dashboard!$B$5),MONTH(Dashboard!$B$5)+A7,1),'Upwork Pipeline'!$K$6:$K$505,"Yes") -> 0
A8: 4 | B8: =DATE(YEAR(Dashboard!$B$5),MONTH(Dashboard!$B$5)+A8-1,1) -> 46357 | C8: =COUNTIFS('Weekly Plan'!$B$5:$B$68,">="&B8,'Weekly Plan'!$B$5:$B$68,"<"&DATE(YEAR(Dashboard!$B$5),MONTH(Dashboard!$B$5)+A8,1),'Weekly Plan'!$G$5:$G$68,"Done") -> 0 | D8: =SUMIFS('Weekly Plan'!$F$5:$F$68,'Weekly Plan'!$B$5:$B$68,">="&B8,'Weekly Plan'!$B$5:$B$68,"<"&DATE(YEAR(Dashboard!$B$5),MONTH(Dashboard!$B$5)+A8,1)) -> 0 | E8: =COUNTIFS('Upwork Pipeline'!$A$6:$A$505,">="&B8,'Upwork Pipeline'!$A$6:$A$505,"<"&DATE(YEAR(Dashboard!$B$5),MONTH(Dashboard!$B$5)+A8,1)) -> 0 | F8: =COUNTIFS('Upwork Pipeline'!$A$6:$A$505,">="&B8,'Upwork Pipeline'!$A$6:$A$505,"<"&DATE(YEAR(Dashboard!$B$5),MONTH(Dashboard!$B$5)+A8,1),'Upwork Pipeline'!$K$6:$K$505,"Yes") -> 0
A9: 5 | B9: =DATE(YEAR(Dashboard!$B$5),MONTH(Dashboard!$B$5)+A9-1,1) -> 46388 | C9: =COUNTIFS('Weekly Plan'!$B$5:$B$68,">="&B9,'Weekly Plan'!$B$5:$B$68,"<"&DATE(YEAR(Dashboard!$B$5),MONTH(Dashboard!$B$5)+A9,1),'Weekly Plan'!$G$5:$G$68,"Done") -> 0 | D9: =SUMIFS('Weekly Plan'!$F$5:$F$68,'Weekly Plan'!$B$5:$B$68,">="&B9,'Weekly Plan'!$B$5:$B$68,"<"&DATE(YEAR(Dashboard!$B$5),MONTH(Dashboard!$B$5)+A9,1)) -> 0 | E9: =COUNTIFS('Upwork Pipeline'!$A$6:$A$505,">="&B9,'Upwork Pipeline'!$A$6:$A$505,"<"&DATE(YEAR(Dashboard!$B$5),MONTH(Dashboard!$B$5)+A9,1)) -> 0 | F9: =COUNTIFS('Upwork Pipeline'!$A$6:$A$505,">="&B9,'Upwork Pipeline'!$A$6:$A$505,"<"&DATE(YEAR(Dashboard!$B$5),MONTH(Dashboard!$B$5)+A9,1),'Upwork Pipeline'!$K$6:$K$505,"Yes") -> 0
A10: 6 | B10: =DATE(YEAR(Dashboard!$B$5),MONTH(Dashboard!$B$5)+A10-1,1) -> 46419 | C10: =COUNTIFS('Weekly Plan'!$B$5:$B$68,">="&B10,'Weekly Plan'!$B$5:$B$68,"<"&DATE(YEAR(Dashboard!$B$5),MONTH(Dashboard!$B$5)+A10,1),'Weekly Plan'!$G$5:$G$68,"Done") -> 0 | D10: =SUMIFS('Weekly Plan'!$F$5:$F$68,'Weekly Plan'!$B$5:$B$68,">="&B10,'Weekly Plan'!$B$5:$B$68,"<"&DATE(YEAR(Dashboard!$B$5),MONTH(Dashboard!$B$5)+A10,1)) -> 0 | E10: =COUNTIFS('Upwork Pipeline'!$A$6:$A$505,">="&B10,'Upwork Pipeline'!$A$6:$A$505,"<"&DATE(YEAR(Dashboard!$B$5),MONTH(Dashboard!$B$5)+A10,1)) -> 0 | F10: =COUNTIFS('Upwork Pipeline'!$A$6:$A$505,">="&B10,'Upwork Pipeline'!$A$6:$A$505,"<"&DATE(YEAR(Dashboard!$B$5),MONTH(Dashboard!$B$5)+A10,1),'Upwork Pipeline'!$K$6:$K$505,"Yes") -> 0
A11: 7 | B11: =DATE(YEAR(Dashboard!$B$5),MONTH(Dashboard!$B$5)+A11-1,1) -> 46447 | C11: =COUNTIFS('Weekly Plan'!$B$5:$B$68,">="&B11,'Weekly Plan'!$B$5:$B$68,"<"&DATE(YEAR(Dashboard!$B$5),MONTH(Dashboard!$B$5)+A11,1),'Weekly Plan'!$G$5:$G$68,"Done") -> 0 | D11: =SUMIFS('Weekly Plan'!$F$5:$F$68,'Weekly Plan'!$B$5:$B$68,">="&B11,'Weekly Plan'!$B$5:$B$68,"<"&DATE(YEAR(Dashboard!$B$5),MONTH(Dashboard!$B$5)+A11,1)) -> 0 | E11: =COUNTIFS('Upwork Pipeline'!$A$6:$A$505,">="&B11,'Upwork Pipeline'!$A$6:$A$505,"<"&DATE(YEAR(Dashboard!$B$5),MONTH(Dashboard!$B$5)+A11,1)) -> 0 | F11: =COUNTIFS('Upwork Pipeline'!$A$6:$A$505,">="&B11,'Upwork Pipeline'!$A$6:$A$505,"<"&DATE(YEAR(Dashboard!$B$5),MONTH(Dashboard!$B$5)+A11,1),'Upwork Pipeline'!$K$6:$K$505,"Yes") -> 0
A12: 8 | B12: =DATE(YEAR(Dashboard!$B$5),MONTH(Dashboard!$B$5)+A12-1,1) -> 46478 | C12: =COUNTIFS('Weekly Plan'!$B$5:$B$68,">="&B12,'Weekly Plan'!$B$5:$B$68,"<"&DATE(YEAR(Dashboard!$B$5),MONTH(Dashboard!$B$5)+A12,1),'Weekly Plan'!$G$5:$G$68,"Done") -> 0 | D12: =SUMIFS('Weekly Plan'!$F$5:$F$68,'Weekly Plan'!$B$5:$B$68,">="&B12,'Weekly Plan'!$B$5:$B$68,"<"&DATE(YEAR(Dashboard!$B$5),MONTH(Dashboard!$B$5)+A12,1)) -> 0 | E12: =COUNTIFS('Upwork Pipeline'!$A$6:$A$505,">="&B12,'Upwork Pipeline'!$A$6:$A$505,"<"&DATE(YEAR(Dashboard!$B$5),MONTH(Dashboard!$B$5)+A12,1)) -> 0 | F12: =COUNTIFS('Upwork Pipeline'!$A$6:$A$505,">="&B12,'Upwork Pipeline'!$A$6:$A$505,"<"&DATE(YEAR(Dashboard!$B$5),MONTH(Dashboard!$B$5)+A12,1),'Upwork Pipeline'!$K$6:$K$505,"Yes") -> 0
A13: 9 | B13: =DATE(YEAR(Dashboard!$B$5),MONTH(Dashboard!$B$5)+A13-1,1) -> 46508 | C13: =COUNTIFS('Weekly Plan'!$B$5:$B$68,">="&B13,'Weekly Plan'!$B$5:$B$68,"<"&DATE(YEAR(Dashboard!$B$5),MONTH(Dashboard!$B$5)+A13,1),'Weekly Plan'!$G$5:$G$68,"Done") -> 0 | D13: =SUMIFS('Weekly Plan'!$F$5:$F$68,'Weekly Plan'!$B$5:$B$68,">="&B13,'Weekly Plan'!$B$5:$B$68,"<"&DATE(YEAR(Dashboard!$B$5),MONTH(Dashboard!$B$5)+A13,1)) -> 0 | E13: =COUNTIFS('Upwork Pipeline'!$A$6:$A$505,">="&B13,'Upwork Pipeline'!$A$6:$A$505,"<"&DATE(YEAR(Dashboard!$B$5),MONTH(Dashboard!$B$5)+A13,1)) -> 0 | F13: =COUNTIFS('Upwork Pipeline'!$A$6:$A$505,">="&B13,'Upwork Pipeline'!$A$6:$A$505,"<"&DATE(YEAR(Dashboard!$B$5),MONTH(Dashboard!$B$5)+A13,1),'Upwork Pipeline'!$K$6:$K$505,"Yes") -> 0
A14: 10 | B14: =DATE(YEAR(Dashboard!$B$5),MONTH(Dashboard!$B$5)+A14-1,1) -> 46539 | C14: =COUNTIFS('Weekly Plan'!$B$5:$B$68,">="&B14,'Weekly Plan'!$B$5:$B$68,"<"&DATE(YEAR(Dashboard!$B$5),MONTH(Dashboard!$B$5)+A14,1),'Weekly Plan'!$G$5:$G$68,"Done") -> 0 | D14: =SUMIFS('Weekly Plan'!$F$5:$F$68,'Weekly Plan'!$B$5:$B$68,">="&B14,'Weekly Plan'!$B$5:$B$68,"<"&DATE(YEAR(Dashboard!$B$5),MONTH(Dashboard!$B$5)+A14,1)) -> 0 | E14: =COUNTIFS('Upwork Pipeline'!$A$6:$A$505,">="&B14,'Upwork Pipeline'!$A$6:$A$505,"<"&DATE(YEAR(Dashboard!$B$5),MONTH(Dashboard!$B$5)+A14,1)) -> 0 | F14: =COUNTIFS('Upwork Pipeline'!$A$6:$A$505,">="&B14,'Upwork Pipeline'!$A$6:$A$505,"<"&DATE(YEAR(Dashboard!$B$5),MONTH(Dashboard!$B$5)+A14,1),'Upwork Pipeline'!$K$6:$K$505,"Yes") -> 0
A15: 11 | B15: =DATE(YEAR(Dashboard!$B$5),MONTH(Dashboard!$B$5)+A15-1,1) -> 46569 | C15: =COUNTIFS('Weekly Plan'!$B$5:$B$68,">="&B15,'Weekly Plan'!$B$5:$B$68,"<"&DATE(YEAR(Dashboard!$B$5),MONTH(Dashboard!$B$5)+A15,1),'Weekly Plan'!$G$5:$G$68,"Done") -> 0 | D15: =SUMIFS('Weekly Plan'!$F$5:$F$68,'Weekly Plan'!$B$5:$B$68,">="&B15,'Weekly Plan'!$B$5:$B$68,"<"&DATE(YEAR(Dashboard!$B$5),MONTH(Dashboard!$B$5)+A15,1)) -> 0 | E15: =COUNTIFS('Upwork Pipeline'!$A$6:$A$505,">="&B15,'Upwork Pipeline'!$A$6:$A$505,"<"&DATE(YEAR(Dashboard!$B$5),MONTH(Dashboard!$B$5)+A15,1)) -> 0 | F15: =COUNTIFS('Upwork Pipeline'!$A$6:$A$505,">="&B15,'Upwork Pipeline'!$A$6:$A$505,"<"&DATE(YEAR(Dashboard!$B$5),MONTH(Dashboard!$B$5)+A15,1),'Upwork Pipeline'!$K$6:$K$505,"Yes") -> 0
A16: 12 | B16: =DATE(YEAR(Dashboard!$B$5),MONTH(Dashboard!$B$5)+A16-1,1) -> 46600 | C16: =COUNTIFS('Weekly Plan'!$B$5:$B$68,">="&B16,'Weekly Plan'!$B$5:$B$68,"<"&DATE(YEAR(Dashboard!$B$5),MONTH(Dashboard!$B$5)+A16,1),'Weekly Plan'!$G$5:$G$68,"Done") -> 0 | D16: =SUMIFS('Weekly Plan'!$F$5:$F$68,'Weekly Plan'!$B$5:$B$68,">="&B16,'Weekly Plan'!$B$5:$B$68,"<"&DATE(YEAR(Dashboard!$B$5),MONTH(Dashboard!$B$5)+A16,1)) -> 0 | E16: =COUNTIFS('Upwork Pipeline'!$A$6:$A$505,">="&B16,'Upwork Pipeline'!$A$6:$A$505,"<"&DATE(YEAR(Dashboard!$B$5),MONTH(Dashboard!$B$5)+A16,1)) -> 0 | F16: =COUNTIFS('Upwork Pipeline'!$A$6:$A$505,">="&B16,'Upwork Pipeline'!$A$6:$A$505,"<"&DATE(YEAR(Dashboard!$B$5),MONTH(Dashboard!$B$5)+A16,1),'Upwork Pipeline'!$K$6:$K$505,"Yes") -> 0
A17: 13 | B17: =DATE(YEAR(Dashboard!$B$5),MONTH(Dashboard!$B$5)+A17-1,1) -> 46631 | C17: =COUNTIFS('Weekly Plan'!$B$5:$B$68,">="&B17,'Weekly Plan'!$B$5:$B$68,"<"&DATE(YEAR(Dashboard!$B$5),MONTH(Dashboard!$B$5)+A17,1),'Weekly Plan'!$G$5:$G$68,"Done") -> 0 | D17: =SUMIFS('Weekly Plan'!$F$5:$F$68,'Weekly Plan'!$B$5:$B$68,">="&B17,'Weekly Plan'!$B$5:$B$68,"<"&DATE(YEAR(Dashboard!$B$5),MONTH(Dashboard!$B$5)+A17,1)) -> 0 | E17: =COUNTIFS('Upwork Pipeline'!$A$6:$A$505,">="&B17,'Upwork Pipeline'!$A$6:$A$505,"<"&DATE(YEAR(Dashboard!$B$5),MONTH(Dashboard!$B$5)+A17,1)) -> 0 | F17: =COUNTIFS('Upwork Pipeline'!$A$6:$A$505,">="&B17,'Upwork Pipeline'!$A$6:$A$505,"<"&DATE(YEAR(Dashboard!$B$5),MONTH(Dashboard!$B$5)+A17,1),'Upwork Pipeline'!$K$6:$K$505,"Yes") -> 0
... A20: 16 | B20: =DATE(YEAR(Dashboard!$B$5),MONTH(Dashboard!$B$5)+A20-1,1) -> 46722 | C20: =COUNTIFS('Weekly Plan'!$B$5:$B$68,">="&B20,'Weekly Plan'!$B$5:$B$68,"<"&DATE(YEAR(Dashboard!$B$5),MONTH(Dashboard!$B$5)+A20,1),'Weekly Plan'!$G$5:$G$68,"Done") -> 0 | D20: =SUMIFS('Weekly Plan'!$F$5:$F$68,'Weekly Plan'!$B$5:$B$68,">="&B20,'Weekly Plan'!$B$5:$B$68,"<"&DATE(YEAR(Dashboard!$B$5),MONTH(Dashboard!$B$5)+A20,1)) -> 0 | E20: =COUNTIFS('Upwork Pipeline'!$A$6:$A$505,">="&B20,'Upwork Pipeline'!$A$6:$A$505,"<"&DATE(YEAR(Dashboard!$B$5),MONTH(Dashboard!$B$5)+A20,1)) -> 0 | F20: =COUNTIFS('Upwork Pipeline'!$A$6:$A$505,">="&B20,'Upwork Pipeline'!$A$6:$A$505,"<"&DATE(YEAR(Dashboard!$B$5),MONTH(Dashboard!$B$5)+A20,1),'Upwork Pipeline'!$K$6:$K$505,"Yes") -> 0
A21: Total | C21: =SUM(C5:C20) -> 1 | D21: =SUM(D5:D20) -> 20 | E21: =SUM(E5:E20) -> 0 | F21: =SUM(F5:F20) -> 0 | G21: =SUM(G5:G20) -> 0 | H21: =SUM(H5:H20) -> 900
H23: Note: the Dashboard reads the last month where column H has a number.
